Traceback (most recent call last):
  File "/Users/boris/miniconda3/envs/tmp1/lib/python3.9/site-packages/jupyter_cache/executors/utils.py", line 58, in single_nb_execution
    executenb(
  File "/Users/boris/miniconda3/envs/tmp1/lib/python3.9/site-packages/nbclient/client.py", line 1314, in execute
    return NotebookClient(nb=nb, resources=resources, km=km, **kwargs).execute()
  File "/Users/boris/miniconda3/envs/tmp1/lib/python3.9/site-packages/jupyter_core/utils/__init__.py", line 165, in wrapped
    return loop.run_until_complete(inner)
  File "/Users/boris/miniconda3/envs/tmp1/lib/python3.9/asyncio/base_events.py", line 647, in run_until_complete
    return future.result()
  File "/Users/boris/miniconda3/envs/tmp1/lib/python3.9/site-packages/nbclient/client.py", line 709, in async_execute
    await self.async_execute_cell(
  File "/Users/boris/miniconda3/envs/tmp1/lib/python3.9/site-packages/nbclient/client.py", line 1062, in async_execute_cell
    await self._check_raise_for_error(cell, cell_index, exec_reply)
  File "/Users/boris/miniconda3/envs/tmp1/lib/python3.9/site-packages/nbclient/client.py", line 918, in _check_raise_for_error
    raise CellExecutionError.from_cell_and_msg(cell, exec_reply_content)
nbclient.exceptions.CellExecutionError: An error occurred while executing the following cell:
------------------
anagram_items = sorted(anagram_dict.items(), key=value_length)
for key, value in anagram_items[-10:]:
    print(value)
------------------


[0;31m---------------------------------------------------------------------------[0m
[0;31mNameError[0m                                 Traceback (most recent call last)
Cell [0;32mIn[95], line 1[0m
[0;32m----> 1[0m anagram_items [38;5;241m=[39m [38;5;28msorted[39m([43managram_dict[49m[38;5;241m.[39mitems(), key[38;5;241m=[39mvalue_length)
[1;32m      2[0m [38;5;28;01mfor[39;00m key, value [38;5;129;01min[39;00m anagram_items[[38;5;241m-[39m[38;5;241m10[39m:]:
[1;32m      3[0m     [38;5;28mprint[39m(value)

[0;31mNameError[0m: name 'anagram_dict' is not defined

